<?xml version='1.0'?>
<sdf version='1.7'>
    <model name='logger0'>
        <link name='logger-chassis'>
            <inertial>
                <pose>0.005952 0 -0.002381 0 -0 0</pose>
                <mass>2.1</mass>
                <inertia>
                    <ixx>0.0332188</ixx>
                    <ixy>0</ixy>
                    <ixz>0.000595238</ixz>
                    <iyy>0.0347069</iyy>
                    <iyz>0</iyz>
                    <izz>0.0640521</izz>
                </inertia>
            </inertial>
            <self_collide>0</self_collide>
            <enable_wind>0</enable_wind>
            <kinematic>0</kinematic>
            <pose>0 0 0 0 -0 0</pose>
            <visual name='logger-chassis_visual'>
                <pose>0 0 0 0 -0 0</pose>
                <geometry>
                    <cylinder>
                        <length>0.1</length>
                        <radius>0.25</radius>
                    </cylinder>
                </geometry>
                <material>
                    <script>
                        <name>Gazebo/Blue</name>
                        <uri>file://media/materials/scripts/gazebo.material</uri>
                    </script>
                    <shader type='pixel'/>
                </material>
                <transparency>0</transparency>
                <cast_shadows>1</cast_shadows>
            </visual>
            <visual name='logger-chassis_fixed_joint_lump__logger-caster_visual_1'>
                <pose>0.125 0 -0.05 0 -0 0</pose>
                <geometry>
                    <sphere>
                        <radius>0.04</radius>
                    </sphere>
                </geometry>
                <material>
                    <script>
                        <name>Gazebo/Grey</name>
                        <uri>file://media/materials/scripts/gazebo.material</uri>
                    </script>
                    <shader type='pixel'/>
                </material>
                <transparency>0</transparency>
                <cast_shadows>1</cast_shadows>
            </visual>
            <collision name='logger-chassis_collision'>
                <laser_retro>0</laser_retro>
                <max_contacts>10</max_contacts>
                <pose>0 0 0 0 -0 0</pose>
                <geometry>
                    <cylinder>
                        <radius>0.25</radius>
                        <length>0.1</length>
                    </cylinder>
                </geometry>
                <surface>
                    <friction>
                        <ode>
                            <mu>0.5</mu>
                            <mu2>0.5</mu2>
                            <fdir1>0 0 0</fdir1>
                            <slip1>0</slip1>
                            <slip2>0</slip2>
                        </ode>
                        <torsional>
                            <coefficient>1</coefficient>
                            <patch_radius>0</patch_radius>
                            <surface_radius>0</surface_radius>
                            <use_patch_radius>1</use_patch_radius>
                            <ode>
                                <slip>0</slip>
                            </ode>
                        </torsional>
                    </friction>
                    <bounce>
                        <restitution_coefficient>0</restitution_coefficient>
                        <threshold>1e+06</threshold>
                    </bounce>
                    <contact>
                        <collide_without_contact>0</collide_without_contact>
                        <collide_without_contact_bitmask>1</collide_without_contact_bitmask>
                        <collide_bitmask>1</collide_bitmask>
                        <ode>
                            <soft_cfm>0</soft_cfm>
                            <soft_erp>0.2</soft_erp>
                            <kp>1e+13</kp>
                            <kd>1</kd>
                            <max_vel>0.01</max_vel>
                            <min_depth>0</min_depth>
                        </ode>
                        <bullet>
                            <split_impulse>1</split_impulse>
                            <split_impulse_penetration_threshold>-0.01</split_impulse_penetration_threshold>
                            <soft_cfm>0</soft_cfm>
                            <soft_erp>0.2</soft_erp>
                            <kp>1e+13</kp>
                            <kd>1</kd>
                        </bullet>
                    </contact>
                </surface>
            </collision>
            <collision name='logger-chassis_fixed_joint_lump__logger-caster_collision_1'>
                <laser_retro>0</laser_retro>
                <max_contacts>10</max_contacts>
                <pose>0.125 0 -0.05 0 -0 0</pose>
                <geometry>
                    <sphere>
                        <radius>0.04</radius>
                    </sphere>
                </geometry>
                <surface>
                    <friction>
                        <ode>
                            <mu>0</mu>
                            <mu2>0</mu2>
                            <fdir1>0 0 0</fdir1>
                            <slip1>0</slip1>
                            <slip2>0</slip2>
                        </ode>
                        <torsional>
                            <coefficient>1</coefficient>
                            <patch_radius>0</patch_radius>
                            <surface_radius>0</surface_radius>
                            <use_patch_radius>1</use_patch_radius>
                            <ode>
                                <slip>0</slip>
                            </ode>
                        </torsional>
                    </friction>
                    <bounce>
                        <restitution_coefficient>0</restitution_coefficient>
                        <threshold>1e+06</threshold>
                    </bounce>
                    <contact>
                        <collide_without_contact>0</collide_without_contact>
                        <collide_without_contact_bitmask>1</collide_without_contact_bitmask>
                        <collide_bitmask>1</collide_bitmask>
                        <ode>
                            <soft_cfm>0</soft_cfm>
                            <soft_erp>0.2</soft_erp>
                            <kp>1e+13</kp>
                            <kd>1</kd>
                            <max_vel>0.01</max_vel>
                            <min_depth>0</min_depth>
                        </ode>
                        <bullet>
                            <split_impulse>1</split_impulse>
                            <split_impulse_penetration_threshold>-0.01</split_impulse_penetration_threshold>
                            <soft_cfm>0</soft_cfm>
                            <soft_erp>0.2</soft_erp>
                            <kp>1e+13</kp>
                            <kd>1</kd>
                        </bullet>
                    </contact>
                </surface>
            </collision>
        </link>
        <link name='logger-hat'>
            <pose>0 -0 0.1 0 -0 0</pose>
            <inertial>
                <pose>0 0 0.04 0 -0 0</pose>
                <mass>0.5</mass>
                <inertia>
                    <ixx>0.000466667</ixx>
                    <ixy>0</ixy>
                    <ixz>0</ixz>
                    <iyy>0.000466667</iyy>
                    <iyz>0</iyz>
                    <izz>0.0001</izz>
                </inertia>
            </inertial>
            <self_collide>0</self_collide>
            <enable_wind>0</enable_wind>
            <kinematic>0</kinematic>
            <visual name='logger-hat_visual'>
                <pose>0 0 0 0 -0 0</pose>
                <geometry>
                    <cylinder>
                        <length>0.1</length>
                        <radius>0.02</radius>
                    </cylinder>
                </geometry>
                <material>
                    <script>
                        <name>Gazebo/Red</name>
                        <uri>file://media/materials/scripts/gazebo.material</uri>
                    </script>
                    <shader type='pixel'/>
                </material>
                <transparency>0</transparency>
                <cast_shadows>1</cast_shadows>
            </visual>
            <collision name='logger-hat_collision'>
                <laser_retro>0</laser_retro>
                <max_contacts>10</max_contacts>
                <pose>0 0 0 0 -0 0</pose>
                <geometry>
                    <cylinder>
                        <radius>0.02</radius>
                        <length>0.1</length>
                    </cylinder>
                </geometry>
                <surface>
                    <friction>
                        <ode>
                            <mu>0</mu>
                            <mu2>0</mu2>
                            <fdir1>0 0 0</fdir1>
                            <slip1>0</slip1>
                            <slip2>0</slip2>
                        </ode>
                        <torsional>
                            <coefficient>1</coefficient>
                            <patch_radius>0</patch_radius>
                            <surface_radius>0</surface_radius>
                            <use_patch_radius>1</use_patch_radius>
                            <ode>
                                <slip>0</slip>
                            </ode>
                        </torsional>
                    </friction>
                    <bounce>
                        <restitution_coefficient>0</restitution_coefficient>
                        <threshold>1e+06</threshold>
                    </bounce>
                    <contact>
                        <collide_without_contact>0</collide_without_contact>
                        <collide_without_contact_bitmask>1</collide_without_contact_bitmask>
                        <collide_bitmask>1</collide_bitmask>
                        <ode>
                            <soft_cfm>0</soft_cfm>
                            <soft_erp>0.2</soft_erp>
                            <kp>1e+13</kp>
                            <kd>1</kd>
                            <max_vel>0.01</max_vel>
                            <min_depth>0</min_depth>
                        </ode>
                        <bullet>
                            <split_impulse>1</split_impulse>
                            <split_impulse_penetration_threshold>-0.01</split_impulse_penetration_threshold>
                            <soft_cfm>0</soft_cfm>
                            <soft_erp>0.2</soft_erp>
                            <kp>1e+13</kp>
                            <kd>1</kd>
                        </bullet>
                    </contact>
                </surface>
            </collision>
        </link>
        <link name='logger-left_wheel'>
            <pose>-0.125 -0.125 0 0 -0 0</pose>
            <inertial>
                <pose>0 0 0 1.5708 -0 0</pose>
                <mass>0.5</mass>
                <inertia>
                    <ixx>0.00107917</ixx>
                    <ixy>0</ixy>
                    <ixz>0</ixz>
                    <iyy>0.00107917</iyy>
                    <iyz>0</iyz>
                    <izz>0.002025</izz>
                </inertia>
            </inertial>
            <self_collide>0</self_collide>
            <enable_wind>0</enable_wind>
            <kinematic>0</kinematic>
            <visual name='logger-left_wheel_visual'>
                <pose>0 0 0 1.5708 -0 0</pose>
                <geometry>
                    <cylinder>
                        <length>0.04</length>
                        <radius>0.09</radius>
                    </cylinder>
                </geometry>
                <material>
                    <script>
                        <name>Gazebo/Wood</name>
                        <uri>file://media/materials/scripts/gazebo.material</uri>
                    </script>
                    <shader type='pixel'/>
                </material>
                <transparency>0</transparency>
                <cast_shadows>1</cast_shadows>
            </visual>
            <collision name='logger-left_wheel_collision'>
                <laser_retro>0</laser_retro>
                <max_contacts>10</max_contacts>
                <pose>0 0 0 1.5708 -0 0</pose>
                <geometry>
                    <cylinder>
                        <radius>0.09</radius>
                        <length>0.04</length>
                    </cylinder>
                </geometry>
                <surface>
                    <friction>
                        <ode>
                            <mu>0.99</mu>
                            <mu2>0.99</mu2>
                            <fdir1>0 0 0</fdir1>
                            <slip1>0</slip1>
                            <slip2>0</slip2>
                        </ode>
                        <torsional>
                            <coefficient>1</coefficient>
                            <patch_radius>0</patch_radius>
                            <surface_radius>0</surface_radius>
                            <use_patch_radius>1</use_patch_radius>
                            <ode>
                                <slip>0</slip>
                            </ode>
                        </torsional>
                    </friction>
                    <bounce>
                        <restitution_coefficient>0</restitution_coefficient>
                        <threshold>1e+06</threshold>
                    </bounce>
                    <contact>
                        <collide_without_contact>0</collide_without_contact>
                        <collide_without_contact_bitmask>1</collide_without_contact_bitmask>
                        <collide_bitmask>1</collide_bitmask>
                        <ode>
                            <soft_cfm>0</soft_cfm>
                            <soft_erp>0.2</soft_erp>
                            <kp>1e+13</kp>
                            <kd>1</kd>
                            <max_vel>0.01</max_vel>
                            <min_depth>0</min_depth>
                        </ode>
                        <bullet>
                            <split_impulse>1</split_impulse>
                            <split_impulse_penetration_threshold>-0.01</split_impulse_penetration_threshold>
                            <soft_cfm>0</soft_cfm>
                            <soft_erp>0.2</soft_erp>
                            <kp>1e+13</kp>
                            <kd>1</kd>
                        </bullet>
                    </contact>
                </surface>
            </collision>
        </link>
        <link name='logger-right_wheel'>
            <pose>-0.125 0.125 -0 0 -0 0</pose>
            <inertial>
                <pose>0 0 0 1.5708 -0 0</pose>
                <mass>0.5</mass>
                <inertia>
                    <ixx>0.00107917</ixx>
                    <ixy>0</ixy>
                    <ixz>0</ixz>
                    <iyy>0.00107917</iyy>
                    <iyz>0</iyz>
                    <izz>0.002025</izz>
                </inertia>
            </inertial>
            <self_collide>0</self_collide>
            <enable_wind>0</enable_wind>
            <kinematic>0</kinematic>
            <visual name='logger-right_wheel_visual'>
                <pose>0 0 0 1.5708 -0 0</pose>
                <geometry>
                    <cylinder>
                        <length>0.04</length>
                        <radius>0.09</radius>
                    </cylinder>
                </geometry>
                <material>
                    <script>
                        <name>Gazebo/Wood</name>
                        <uri>file://media/materials/scripts/gazebo.material</uri>
                    </script>
                    <shader type='pixel'/>
                </material>
                <transparency>0</transparency>
                <cast_shadows>1</cast_shadows>
            </visual>
            <collision name='logger-right_wheel_collision'>
                <laser_retro>0</laser_retro>
                <max_contacts>10</max_contacts>
                <pose>0 0 0 1.5708 -0 0</pose>
                <geometry>
                    <cylinder>
                        <radius>0.09</radius>
                        <length>0.04</length>
                    </cylinder>
                </geometry>
                <surface>
                    <friction>
                        <ode>
                            <mu>0.99</mu>
                            <mu2>0.99</mu2>
                            <fdir1>0 0 0</fdir1>
                            <slip1>0</slip1>
                            <slip2>0</slip2>
                        </ode>
                        <torsional>
                            <coefficient>1</coefficient>
                            <patch_radius>0</patch_radius>
                            <surface_radius>0</surface_radius>
                            <use_patch_radius>1</use_patch_radius>
                            <ode>
                                <slip>0</slip>
                            </ode>
                        </torsional>
                    </friction>
                    <bounce>
                        <restitution_coefficient>0</restitution_coefficient>
                        <threshold>1e+06</threshold>
                    </bounce>
                    <contact>
                        <collide_without_contact>0</collide_without_contact>
                        <collide_without_contact_bitmask>1</collide_without_contact_bitmask>
                        <collide_bitmask>1</collide_bitmask>
                        <ode>
                            <soft_cfm>0</soft_cfm>
                            <soft_erp>0.2</soft_erp>
                            <kp>1e+13</kp>
                            <kd>1</kd>
                            <max_vel>0.01</max_vel>
                            <min_depth>0</min_depth>
                        </ode>
                        <bullet>
                            <split_impulse>1</split_impulse>
                            <split_impulse_penetration_threshold>-0.01</split_impulse_penetration_threshold>
                            <soft_cfm>0</soft_cfm>
                            <soft_erp>0.2</soft_erp>
                            <kp>1e+13</kp>
                            <kd>1</kd>
                        </bullet>
                    </contact>
                </surface>
            </collision>
        </link>
        <joint name='logger-chassis2hat' type='revolute'>
            <parent>logger-chassis</parent>
            <child>logger-hat</child>
            <pose>0 0 0 0 -0 0</pose>
            <axis>
                <xyz>0 0 1</xyz>
                <limit>
                    <lower>-1e+16</lower>
                    <upper>1e+16</upper>
                    <effort>-1</effort>
                    <velocity>-1</velocity>
                </limit>
                <dynamics>
                    <spring_reference>0</spring_reference>
                    <spring_stiffness>0</spring_stiffness>
                    <damping>0</damping>
                    <friction>0</friction>
                </dynamics>
            </axis>
            <physics>
                <ode>
                    <limit>
                        <cfm>0</cfm>
                        <erp>0.2</erp>
                    </limit>
                    <suspension>
                        <cfm>0</cfm>
                        <erp>0.2</erp>
                    </suspension>
                </ode>
            </physics>
        </joint>
        <joint name='logger-chassis2left_wheel' type='revolute'>
            <parent>logger-chassis</parent>
            <child>logger-left_wheel</child>
            <pose>0 0 0 0 -0 0</pose>
            <axis>
                <xyz>0 1 0</xyz>
                <limit>
                    <lower>-1e+16</lower>
                    <upper>1e+16</upper>
                    <effort>-1</effort>
                    <velocity>-1</velocity>
                </limit>
                <dynamics>
                    <spring_reference>0</spring_reference>
                    <spring_stiffness>0</spring_stiffness>
                    <damping>0</damping>
                    <friction>0</friction>
                </dynamics>
            </axis>
            <physics>
                <ode>
                    <limit>
                        <cfm>0</cfm>
                        <erp>0.2</erp>
                    </limit>
                    <suspension>
                        <cfm>0</cfm>
                        <erp>0.2</erp>
                    </suspension>
                </ode>
            </physics>
        </joint>
        <joint name='logger-chassis2right_wheel' type='revolute'>
            <parent>logger-chassis</parent>
            <child>logger-right_wheel</child>
            <pose>0 0 0 0 -0 0</pose>
            <axis>
                <xyz>0 1 0</xyz>
                <limit>
                    <lower>-1e+16</lower>
                    <upper>1e+16</upper>
                    <effort>-1</effort>
                    <velocity>-1</velocity>
                </limit>
                <dynamics>
                    <spring_reference>0</spring_reference>
                    <spring_stiffness>0</spring_stiffness>
                    <damping>0</damping>
                    <friction>0</friction>
                </dynamics>
            </axis>
            <physics>
                <ode>
                    <limit>
                        <cfm>0</cfm>
                        <erp>0.2</erp>
                    </limit>
                    <suspension>
                        <cfm>0</cfm>
                        <erp>0.2</erp>
                    </suspension>
                </ode>
            </physics>
        </joint>
        <static>0</static>
        <allow_auto_disable>1</allow_auto_disable>
        <plugin name='differential_drive_controller' filename='libgazebo_ros_diff_drive.so'>
            <legacyMode>0</legacyMode>
            <alwaysOn>1</alwaysOn>
            <updateRate>100</updateRate>
            <leftJoint>logger-chassis2left_wheel</leftJoint>
            <rightJoint>logger-chassis2right_wheel</rightJoint>
            <wheelSeparation>0.25</wheelSeparation>
            <wheelDiameter>0.18</wheelDiameter>
            <wheelTorque>1</wheelTorque>
            <commandTopic>ddr_0/cmd_vel</commandTopic>
            <odometryTopic>ddr_0/odom</odometryTopic>
            <odometryFrame>odom</odometryFrame>
            <robotBaseFrame>logger-chassis</robotBaseFrame>
            <robotNamespace>/</robotNamespace>
        </plugin>
    </model>
</sdf>
